<mujoco model="cartpole">
  <option timestep="0.002" gravity="0 0 -9.81"/>
  <worldbody>
    <light pos="0 0 3" dir="0 0 -1"/>
    <geom name="floor" type="plane" size="2 2 0.1" rgba="0.8 0.9 0.8 1"/>
    <body name="cart" pos="0 0 0.2">
      <joint name="slider" type="slide" axis="1 0 0" range="-1.5 1.5"/>
      <geom name="cart_geom" type="box" size="0.2 0.15 0.1"
            rgba="0.7 0.2 0.2 1" mass="1.0"/>
      <body name="pole" pos="0 0 0.1">
        <joint name="hinge" type="hinge" axis="0 1 0"/>
        <geom name="pole_geom" type="capsule" size="0.04 0.4"
              pos="0 0 0.4" rgba="0.2 0.7 0.2 1" mass="0.1"/>
      </body>
    </body>
  </worldbody>
  <actuator>
    <motor name="slide_motor" joint="slider"
           ctrlrange="-1 1" ctrllimited="true" gear="10"/>
  </actuator>
</mujoco>
