<mujoco model="walker2d">
  <compiler angle="radian" inertiafromgeom="true"/>
  <default>
    <joint limited="true" damping=".05" armature=".1"/>
    <geom contype="1" conaffinity="1" condim="3" density="1000"
          friction="0.7 0.1 0.1"/>
  </default>
  <option timestep="0.002" integrator="Euler"/>
  <asset>
    <texture type="skybox" builtin="gradient" rgb1=".4 .5 .6"
             rgb2="0 0 0" width="100" height="100"/>
    <texture builtin="checker" height="100" name="texplane"
             rgb1="0 0 0" rgb2=".8 .8 .8" type="2d" width="100"/>
    <material name="MatPlane" reflectance="0.5" shininess="1"
              specular="1" texrepeat="60 60" texture="texplane"/>
  </asset>
  <worldbody>
    <light cutoff="100" diffuse="1 1 1" dir="0 0 -1.3"
           directional="true" pos="0 0 1.3" specular=".1 .1 .1"/>
    <geom conaffinity="1" condim="3" name="floor" pos="0 0 0"
          rgba=".8 .9 .8 1" size="40 40 40" type="plane"
          material="MatPlane"/>
    <body name="torso" pos="0 0 1.25">
      <camera name="track" mode="trackcom" pos="0 -5 0.8"
              xyaxes="1 0 0 0 0 1" fovy="45"/>
      <joint armature="0" damping="0" limited="false"
             name="rootx" type="slide" axis="1 0 0"/>
      <joint armature="0" damping="0" limited="false"
             name="rootz" type="slide" axis="0 0 1" ref="1.25"/>
      <joint armature="0" damping="0" limited="false"
             name="rooty" type="hinge" axis="0 1 0"/>
      <geom friction="0.9" fromto="0 0 0.07 0 0 0.45"
            name="torso_geom" size="0.05" type="capsule"/>
      <body name="thigh" pos="0 0 0.07">
        <joint axis="0 -1 0" name="thigh_joint"
               range="-2.6 0.05" type="hinge"/>
        <geom friction="0.9" fromto="0 0 0 0 0 -0.45"
              name="thigh_geom" size="0.05" type="capsule"/>
        <body name="leg" pos="0 0 -0.45">
          <joint axis="0 -1 0" name="leg_joint"
                 range="-2.6 -0.1" type="hinge"/>
          <geom friction="0.9" fromto="0 0 0 0 0 -0.5"
                name="leg_geom" size="0.04" type="capsule"/>
          <body name="foot" pos="0 0 -0.5">
            <joint axis="0 -1 0" name="foot_joint"
                   range="-0.8 0.8" type="hinge"/>
            <geom friction="0.9" fromto="-0.2 0 0 0.2 0 0"
                  name="foot_geom" size="0.06" type="capsule"
                  contype="1" conaffinity="1"/>
          </body>
        </body>
      </body>
      <body name="thigh_left" pos="0 0 0.07">
        <joint axis="0 -1 0" name="thigh_left_joint"
               range="-2.6 0.05" type="hinge"/>
        <geom friction="0.9" fromto="0 0 0 0 0 -0.45"
              name="thigh_left_geom" size="0.05" type="capsule"/>
        <body name="leg_left" pos="0 0 -0.45">
          <joint axis="0 -1 0" name="leg_left_joint"
                 range="-2.6 -0.1" type="hinge"/>
          <geom friction="0.9" fromto="0 0 0 0 0 -0.5"
                name="leg_left_geom" size="0.04" type="capsule"/>
          <body name="foot_left" pos="0 0 -0.5">
            <joint axis="0 -1 0" name="foot_left_joint"
                   range="-0.8 0.8" type="hinge"/>
            <geom friction="0.9" fromto="-0.2 0 0 0.2 0 0"
                  name="foot_left_geom" size="0.06" type="capsule"
                  contype="1" conaffinity="1"/>
          </body>
        </body>
      </body>
    </body>
  </worldbody>
  <actuator>
    <motor ctrllimited="true" ctrlrange="-1 1" gear="100" joint="thigh_joint"/>
    <motor ctrllimited="true" ctrlrange="-1 1" gear="100" joint="leg_joint"/>
    <motor ctrllimited="true" ctrlrange="-1 1" gear="100" joint="foot_joint"/>
    <motor ctrllimited="true" ctrlrange="-1 1" gear="100" joint="thigh_left_joint"/>
    <motor ctrllimited="true" ctrlrange="-1 1" gear="100" joint="leg_left_joint"/>
    <motor ctrllimited="true" ctrlrange="-1 1" gear="100" joint="foot_left_joint"/>
  </actuator>
</mujoco>
